<?xml version="1.0" ?>
<!-- =================================================================================== -->
<!-- |    This document was autogenerated by xacro from vision60.urdf.xacro            | -->
<!-- |    EDITING THIS FILE BY HAND IS NOT RECOMMENDED                                 | -->
<!-- =================================================================================== -->


<robot name="srbx2" xmlns:xacro="http://www.ros.org/wiki/xacro">
  <!-- Define materials -->
  <material name="gray">
    <color rgba="0.5 0.5 0.5 0.7"/>
  </material>
  <material name="darkgray">
    <color rgba="0.3 0.3 0.3 1.0"/>
  </material>
  <material name="blue">
    <color rgba="0 0 0.8 1"/>
  </material>
  <material name="black">
    <color rgba="0 0 0 1"/>
  </material>
  <material name="purple">
    <color rgba="0.5 0.0 0.5 1.0"/>
  </material>
  <material name="red">
    <color rgba="0.8 0.0 0.2 1.0"/>
  </material>
  <material name="white">
    <color rgba="1 1 1 0.9"/>
  </material>
  <material name="ctorange">
    <color rgba="1.0 0.43137254902 0.117647058824 1"/>
  </material>

  <gazebo>
    <plugin filename="libgazebo_ros_control.so" name="gazebo_ros_control">
      <robotNamespace>/srbx2</robotNamespace>
      <controlPeriod>0.001</controlPeriod> <!-- 1000Hz -->
      <robotSimType>gazebo_ros_control/DefaultRobotHWSim</robotSimType>
      <legacyModeNS>true</legacyModeNS>
    </plugin>
  </gazebo>

  <!-- body1-rol0-fake0-pitch0-fake1-yaw0-barbetween-yaw1-fake2-pitch1-fake3-roll1-body2 -->
  <!-- Body -->
  <link name="body1">
    <visual>
      <origin rpy="0 0 0" xyz="0 0 0"/>
      <geometry>
        <mesh filename="/meshes/trunk.dae" scale="1 1 1"/>
      </geometry>
      <material name="black"/>
    </visual>
    <collision>
      <origin rpy="0 0 0" xyz="0 0 0"/>
      <geometry>
        <box size="0.267 0.194 0.114"/>
      </geometry>
    </collision>
    <inertial>
      <!--<origin rpy="0 0 0" xyz="0.0 0.0041 -0.0005"/>-->
      <origin rpy="0 0 0" xyz="0.0 0.0 0.0"/>
      <!--<mass value="6.0"/>-->
      <mass value="12.4530"/>
      <!--<inertia ixx="0.0158533" ixy="-3.66e-05" ixz="-6.11e-05" iyy="0.0377999" iyz="-2.75e-05" izz="0.0456542"/>-->
      <inertia ixx="0.01683993" ixy="8.3902e-5" ixz="0.000597679" iyy="0.056579028" iyz="2.5134e-5" izz="0.064713601"/>
    </inertial>
  </link>

  <!-- fake0 -->
  <link name="fakelink0">
    <visual>
      <origin rpy="0 0 0" xyz="0.0 0.0 0.0"/>
      <geometry>
        <box size="0.03 0.03 0.03"/>
      </geometry>
      <material name="gray"/>
    </visual>
    <!--<collision>
      <origin rpy="1.5707963268 0 0" xyz="0.0 -0.039 0"/>
      <geometry>
        <box size="0.195 0.1 0.17"/>
      </geometry>
    </collision>-->
    <inertial>
      <origin xyz="0 0 0"/>
      <mass value="0.00000000001"/>
      <inertia ixx="0.0001" ixy="0" ixz="0" iyy="0.0001" iyz="0" izz="0.0001"/>
    </inertial>
  </link>
  <!-- fake roll -->
  <joint name="Roll0" type="revolute">
    <parent link="body1"/>
    <child link="fakelink0"/>
    <axis xyz="1 0 0"/>
    <origin xyz="0.0 0.0 0.15"/>
    <limit effort="375" lower="-3.0" upper="3.0" velocity="8.6"/>
    <dynamics damping="0.0" friction="0.0"/>
  </joint>

  <!-- fake1 -->
  <link name="fakelink1">
    <visual>
      <origin rpy="0 0 0" xyz="0.0 0.0 0.0"/>
      <geometry>
        <box size="0.03 0.03 0.03"/>
      </geometry>
      <material name="gray"/>
    </visual>
    <!--<collision>
      <origin rpy="1.5707963268 0 0" xyz="0.0 -0.039 0"/>
      <geometry>
        <box size="0.195 0.1 0.17"/>
      </geometry>
    </collision>-->
    <inertial>
      <origin xyz="0 0 0"/>
      <mass value="0.00000000001"/>
      <inertia ixx="0.0001" ixy="0" ixz="0" iyy="0.0001" iyz="0" izz="0.0001"/>
    </inertial>
  </link>
  <!-- fake pitch -->
  <joint name="Pitch0" type="revolute">
    <parent link="fakelink0"/>
    <child link="fakelink1"/>
    <axis xyz="0 1 0"/>
    <origin xyz="0 0.0 0"/>
    <!--  rpy="0 -0.3 0" -->
    <limit effort="375" lower="-3.0" upper="3.0" velocity="8.6"/>
    <dynamics damping="0.0" friction="0.0"/>
  </joint>

  <!-- bar between -->
  <link name="barbetween">
    <visual>
      <origin rpy="0 0 0" xyz="0.0 -0.5 0.0"/>
      <geometry>
        <box size="0.02 1.0 0.02"/>
      </geometry>
      <material name="blue"/>
    </visual>
    <!--<collision>
      <origin rpy="1.5707963268 0 0" xyz="0.0 -0.039 0"/>
      <geometry>
        <box size="0.195 0.1 0.17"/>
      </geometry>
    </collision>-->
    <inertial>
      <origin xyz="0 -0.5 0"/>
      <!-- <mass value="0.00000000001"/> -->
      <mass value="0.0000000001"/>
      <inertia ixx="0.0001" ixy="0" ixz="0" iyy="0.0001" iyz="0" izz="0.0001"/>
    </inertial>
  </link>
  <!-- fake yaw -->
  <joint name="Yaw0" type="revolute">
    <parent link="fakelink1"/>
    <child link="barbetween"/>
    <axis xyz="0 0 1"/>
    <origin xyz="0 0.0 0"/>
    <!--  rpy="0 -0.3 0" -->
    <limit effort="375" lower="-3.0" upper="3.0" velocity="8.6"/>
    <dynamics damping="0.0" friction="0.0"/>
  </joint>

  <!-- fake2 -->
  <link name="fakelink2">
    <visual>
      <origin rpy="0 0 0" xyz="0.0 0.0 0.0"/>
      <geometry>
        <box size="0.03 0.03 0.03"/>
      </geometry>
      <material name="gray"/>
    </visual>
    <!--<collision>
      <origin rpy="1.5707963268 0 0" xyz="0.0 -0.039 0"/>
      <geometry>
        <box size="0.195 0.1 0.17"/>
      </geometry>
    </collision>-->
    <inertial>
      <origin xyz="0 0 0"/>
      <mass value="0.00000000001"/>
      <inertia ixx="0.0001" ixy="0" ixz="0" iyy="0.0001" iyz="0" izz="0.0001"/>
    </inertial>
  </link>
  <!-- fake yaw -->
  <joint name="Yaw1" type="revolute">
    <parent link="barbetween"/>
    <child link="fakelink2"/>
    <axis xyz="0 0 1"/>
    <origin xyz="0 -1 0"/>
    <!--  rpy="0 -0.3 0" -->
    <limit effort="375" lower="-3.0" upper="3.0" velocity="8.6"/>
    <dynamics damping="0.0" friction="0.0"/>
  </joint>

  <!-- fake3 -->
  <link name="fakelink3">
    <visual>
      <origin rpy="0 0 0" xyz="0.0 0.0 0.0"/>
      <geometry>
        <box size="0.03 0.03 0.03"/>
      </geometry>
      <material name="gray"/>
    </visual>
    <!--<collision>
      <origin rpy="1.5707963268 0 0" xyz="0.0 -0.039 0"/>
      <geometry>
        <box size="0.195 0.1 0.17"/>
      </geometry>
    </collision>-->
    <inertial>
      <origin xyz="0 0 0"/>
      <mass value="0.00000000001"/>
      <inertia ixx="0.0001" ixy="0" ixz="0" iyy="0.0001" iyz="0" izz="0.0001"/>
    </inertial>
  </link>
  <!-- fake pitch -->
  <joint name="Pitch1" type="revolute">
    <parent link="fakelink2"/>
    <child link="fakelink3"/>
    <axis xyz="0 1 0"/>
    <origin xyz="0 0.0 0"/>
    <!--  rpy="0 -0.3 0" -->
    <limit effort="375" lower="-3.0" upper="3.0" velocity="8.6"/>
    <dynamics damping="0.0" friction="0.0"/>
  </joint>

  <!-- body2fakeframe -->
  <link name="body2framelink">
    <visual>
      <origin rpy="0 0 0" xyz="0 0 -0.15"/>
      <geometry>
        <box size="0.00001 0.00001 0.00001"/>
      </geometry>
      <material name="gray"/>
    </visual>
    <inertial>
      <origin xyz="0 0 0"/>
      <!-- Uniform box -->
      <!-- <mass value="12"/>
      <inertia ixx="0.0986" ixy="0" ixz="0" iyy="0.8105" iyz="0" izz="0.8369"/> -->
      <!-- Based on solidworks and added battery -->
      <mass value="0.00000000001"/>
      <inertia ixx="0.0001" ixy="0" ixz="0" iyy="0.0001" iyz="0" izz="0.0001"/>
    </inertial>
    <!-- Just copy geometry for collision -->
    <!--<collision>
      <origin rpy="0 0 0" xyz="0 0 -0.15"/>
      <geometry>
        <box size="0.88 0.25 0.19"/>
      </geometry>
    </collision>-->
  </link>
  <!-- fake roll -->
  <joint name="Roll1" type="revolute">
    <parent link="fakelink3"/>
    <child link="body2framelink"/>
    <axis xyz="1 0 0"/>
    <origin xyz="0 0.0 0"/>
    <!--  rpy="0 -0.3 0" -->
    <limit effort="375" lower="-3.0" upper="3.0" velocity="8.6"/>
    <dynamics damping="0.0" friction="0.0"/>
  </joint>

  <!-- body2 -->
  <link name="body2">
    <visual>
      <origin rpy="0 0 0" xyz="0 0 0"/>
      <geometry>
        <mesh filename="/meshes/trunk.dae" scale="1 1 1"/>
      </geometry>
      <material name="black"/>
    </visual>
    <collision>
      <origin rpy="0 0 0" xyz="0 0 0"/>
      <geometry>
        <box size="0.267 0.194 0.114"/>
      </geometry>
    </collision>
    <inertial>
      <!--<origin rpy="0 0 0" xyz="0.0 0.0041 -0.0005"/>-->
      <origin rpy="0 0 0" xyz="0.0 0.0 0.0"/>
      <!--<mass value="6.0"/>-->
      <mass value="12.4530"/>
      <!--<inertia ixx="0.0158533" ixy="-3.66e-05" ixz="-6.11e-05" iyy="0.0377999" iyz="-2.75e-05" izz="0.0456542"/>-->
      <inertia ixx="0.01683993" ixy="8.3902e-5" ixz="0.000597679" iyy="0.056579028" iyz="2.5134e-5" izz="0.064713601"/>
    </inertial>
  </link>
  <!-- fake bodyjoint -->
  <joint name="body2jointframe" type="fixed">
    <parent link="body2framelink"/>
    <child link="body2"/>
    <!--<axis xyz="1 0 0"/>-->
    <origin xyz="0 0.0 -0.15"/>
    <!--  rpy="0 -0.3 0" -->
    <!--<limit effort="375" lower="-3.0" upper="3.0" velocity="8.6"/>
    <dynamics damping="0.0" friction="0.0"/>-->
  </joint>
  

<transmission name="Roll0Transmission">
    <type> transmission_interface/SimpleTransmission </type>
    <joint name="Roll0">
        <hardwareInterface>hardware_interface/EffortJointInterface</hardwareInterface>
    </joint>
    <actuator name="Roll0motor">
      <mechanicalReduction>18.545</mechanicalReduction>
      <motorInertia>0.0001</motorInertia>
      <hardwareInterface>hardware_interface/EffortJointInterface</hardwareInterface>
    </actuator>
</transmission>
<transmission name="Roll1Transmission">
    <type> transmission_interface/SimpleTransmission </type>
    <joint name="Roll1">
        <hardwareInterface>hardware_interface/EffortJointInterface</hardwareInterface>
    </joint>
    <actuator name="Roll1motor">
      <mechanicalReduction>18.545</mechanicalReduction>
      <motorInertia>0.0001</motorInertia>
      <hardwareInterface>hardware_interface/EffortJointInterface</hardwareInterface>
    </actuator>
</transmission>

<transmission name="Pitch0Transmission">
    <type> transmission_interface/SimpleTransmission </type>
    <joint name="Pitch0">
        <hardwareInterface>hardware_interface/EffortJointInterface</hardwareInterface>
    </joint>
    <actuator name="Pitch0motor">
      <mechanicalReduction>25</mechanicalReduction>
      <motorInertia>0.0001</motorInertia>
      <hardwareInterface>hardware_interface/EffortJointInterface</hardwareInterface>
    </actuator>
</transmission>
<transmission name="Pitch1Transmission">
    <type> transmission_interface/SimpleTransmission </type>
    <joint name="Pitch1">
        <hardwareInterface>hardware_interface/EffortJointInterface</hardwareInterface>
    </joint>
    <actuator name="Pitch1motor">
      <mechanicalReduction>25</mechanicalReduction>
      <motorInertia>0.0001</motorInertia>
      <hardwareInterface>hardware_interface/EffortJointInterface</hardwareInterface>
    </actuator>
</transmission>

<transmission name="Yaw0Transmission">
    <type> transmission_interface/SimpleTransmission </type>
    <joint name="Yaw0">
        <hardwareInterface>hardware_interface/EffortJointInterface</hardwareInterface>
    </joint>
    <actuator name="Yaw0motor">
      <mechanicalReduction>25</mechanicalReduction>
      <motorInertia>0.0001</motorInertia>
      <hardwareInterface>hardware_interface/EffortJointInterface</hardwareInterface>
    </actuator>
</transmission>
<transmission name="Yaw1Transmission">
    <type> transmission_interface/SimpleTransmission </type>
    <joint name="Yaw1">
        <hardwareInterface>hardware_interface/EffortJointInterface</hardwareInterface>
    </joint>
    <actuator name="Yaw1motor">
      <mechanicalReduction>25</mechanicalReduction>
      <motorInertia>0.0001</motorInertia>
      <hardwareInterface>hardware_interface/EffortJointInterface</hardwareInterface>
    </actuator>
</transmission>


</robot>